Workbook

Sheet consolidated sheet
A1: Sl No | B1: Particulars | C1: Project | N1: HMA HR Revenue | O1: LSGB | P1: Total
C2: HLL Malappuram | D2: Power Grid Corporation of India Limited - Yelahanka, Bangalore | E2: Cochin Shipyard Limited - Andaman | F2: IOCL - Panipat | G2: HLL Cotton Hill, Trivandrum | H2: Swasthya-An innovative behaviour change programme for Aneamia in women of reproductive age | I2: Counselling support for transgender individuals-pre and post surgery and non surgical pathways in gender transition | J2: Inclusive community mental health initiative in Wayanad district | K2: My City | L2: Exploring the correlation and Diagnostic potential of Menstrual Blood | M2: HLL Maharashtra
A3: 1 | B3: HMA Core TeamSalary @5% | C3: ='CORE MANPOWER'!AF4 -> 5007 | D3: ='CORE MANPOWER'!AG4 -> 8409 | E3: ='CORE MANPOWER'!AH4 -> 6250 | F3: ='CORE MANPOWER'!AI4 -> 0 | G3: ='CORE MANPOWER'!AJ4 -> 0 | H3: ='CORE MANPOWER'!AK4 -> 5556 | I3: ='CORE MANPOWER'!AL4 -> 5877 | J3: ='CORE MANPOWER'!AM4 -> 10714 | ... M3: ='CORE MANPOWER'!AP4 -> 0 | N3: 0 | O3: ='CORE MANPOWER'!AQ4 -> 648949.77 | P3: =SUM(C3:O3) -> 690762.77
A4: 2 | B4: HR Expenses @5% | C4: ='JULY 2025 ADMIN EXPENSES'!I9 -> 11200.25 | D4: ='JULY 2025 ADMIN EXPENSES'!J9 -> 11200.25 | E4: ='JULY 2025 ADMIN EXPENSES'!K9 -> 11200.25 | F4: ='JULY 2025 ADMIN EXPENSES'!L9 -> 0 | G4: ='JULY 2025 ADMIN EXPENSES'!M9 -> 0 | H4: ='JULY 2025 ADMIN EXPENSES'!N9 -> 11200.25 | I4: ='JULY 2025 ADMIN EXPENSES'!O9 -> 0 | J4: ='JULY 2025 ADMIN EXPENSES'!P9 -> 0 | ... M4: ='JULY 2025 ADMIN EXPENSES'!S9 -> 0 | N4: 0 | O4: ='JULY 2025 ADMIN EXPENSES'!T9+'JULY 2025 ADMIN EXPENSES'!U9 -> 80759 | P4: =SUM(C4:O4) -> 125560
A5: 3 | B5: HMA Admin Expenses @5% | C5: ='JULY 2025 ADMIN EXPENSES'!W3 -> 0 | D5: ='JULY 2025 ADMIN EXPENSES'!X3 -> 0 | E5: ='JULY 2025 ADMIN EXPENSES'!Y3 -> 0 | F5: ='JULY 2025 ADMIN EXPENSES'!Z3 -> 0 | G5: ='JULY 2025 ADMIN EXPENSES'!AA3 -> 0 | H5: ='JULY 2025 ADMIN EXPENSES'!AB3 -> 0 | I5: ='JULY 2025 ADMIN EXPENSES'!AC3 -> 0 | J5: ='JULY 2025 ADMIN EXPENSES'!AD3 -> 0 | ... N5: ='JULY 2025 ADMIN EXPENSES'!AH3 -> 60000 | O5: ='JULY 2025 ADMIN EXPENSES'!AI11+'JULY 2025 ADMIN EXPENSES'!AI12+'JULY 2025 ADMIN EXPENSES'!AI13+'JULY 2025 ADMIN EXPENSES'!AI14+'JULY 2025 ADMIN EXPENSES'!AI15+'JULY 2025 ADMIN EXPENSES'!AI16+'JULY 2025 ADMIN EXPENSES'!AI17+'JULY 2025 ADMIN EXPENSES'!AI18+'JULY 2025 ADMIN EXPENSES'!AI19+'JULY 2025 ADMIN EXPENSES'!AI20+'JULY 2025 ADMIN EXPENSES'!AI21+'JULY 2025 ADMIN EXPENSES'!AI22+'JULY 2025 ADMIN EXPENSES'!AI23+'JULY 2025 ADMIN EXPENSES'!AI24+'JULY 2025 ADMIN EXPENSES'!AI25+'JULY 2025 ADMIN EXPENSES'!AI26+'JULY 2025 ADMIN EXPENSES'!AI27+'JULY 2025 ADMIN EXPENSES'!AI28 -> 261607 | P5: =SUM(C5:O5) -> 329940.33
A6: TOTAL | C6: =SUM(C3:C5) -> 16207.25 | D6: =SUM(D3:D5) -> 19609.25 | E6: =SUM(E3:E5) -> 17450.25 | F6: =SUM(F3:F5) -> 0 | G6: =SUM(G3:G5) -> 0 | H6: =SUM(H3:H5) -> 16756.25 | I6: =SUM(I3:I5) -> 5877 | J6: =SUM(J3:J5) -> 10714 | ... P6: =SUM(P3:P5) -> 1146263.1
A9: Sl No | B9: Particulars | C9: Project | N9: HMA HR Revenue | O9: LSGB | P9: Total
C10: HLL Malappuram | D10: Power Grid Corporation of India Limited - Yelahanka, Bangalore | E10: Cochin Shipyard Limited - Andaman | F10: IOCL - Panipat | G10: HLL Cotton Hill, Trivandrum | H10: Swasthya-An innovative behaviour change programme for Aneamia in women of reproductive age | I10: Counselling support for transgender individuals-pre and post surgery and non surgical pathways in gender transition | J10: Inclusive community mental health initiative in Wayanad district | K10: My City | L10: Exploring the correlation and Diagnostic potential of Menstrual Blood | M10: HLL Maharashtra
A11: 1 | B11: HMA Core TeamSalary @5% | C11: =C3/P3*100 -> 0.72485087 | D11: =D3/P3*100 -> 1.2173499 | E11: =E3/P3*100 -> 0.90479688 | F11: =F3/P3*100 -> 0 | G11: =G3/P3*100 -> 0 | H11: =H3/P3*100 -> 0.80432823 | I11: =I3/P3*100 -> 0.8507986 | J11: =J3/P3*100 -> 1.551039 | K11: =K3/P3*100 -> 0 | L11: =L3/P3*100 -> 0 | M11: =M3/P3*100 -> 0 | N11: =N3/P3*100 -> 0 | O11: =O3/P3*100 -> 93.946837 | P11: =P3/P3*100 -> 100
A12: 2 | B12: HR Expenses @5% | C12: =C4/P4*100 -> 8.9202373 | D12: =D4/P4*100 -> 8.9202373 | E12: =E4/P4*100 -> 8.9202373 | F12: =F4/P4*100 -> 0 | G12: =G4/P4*100 -> 0 | H12: =H4/P4*100 -> 8.9202373 | I12: =I4/P4*100 -> 0 | J12: =J4/P4*100 -> 0 | K12: =K4/P4*100 -> 0 | L12: =L4/P4*100 -> 0 | M12: =M4/P4*100 -> 0 | N12: =N4/P4*100 -> 0 | O12: =O4/P4*100 -> 64.319051 | P12: =P4/P4*100 -> 100
A13: 3 | B13: HMA Admin Expenses @5% | C13: =C5/P5*100 -> 0 | D13: =D5/P5*100 -> 0 | E13: =E5/P5*100 -> 0 | F13: =F5/P5*100 -> 0 | G13: =G5/P5*100 -> 0 | H13: =H5/P5*100 -> 0 | I13: =I5/P5*100 -> 0 | J13: =J5/P5*100 -> 0 | K13: =K5/P5*100 -> 2.5257092 | L13: =L5/P5*100 -> 0 | M13: =M5/P5*100 -> 0 | N13: =N5/P5*100 -> 18.185106 | O13: =O5/P5*100 -> 79.289185 | P13: =P5/P5*100 -> 100
A14: TOTAL | C14: =C6/P6*100 -> 1.4139206 | D14: =D6/P6*100 -> 1.7107111 | E14: =E6/P6*100 -> 1.5223599 | F14: =F6/P6*100 -> 0 | G14: =G6/P6*100 -> 0 | H14: =H6/P6*100 -> 1.4618153 | I14: =I6/P6*100 -> 0.51270951 | J14: =J6/P6*100 -> 0.93468942 | K14: =K6/P6*100 -> 0.72700005 | L14: =L6/P6*100 -> 0 | M14: =M6/P6*100 -> 0 | N14: =N6/P6*100 -> 5.2344003 | O14: =O6/P6*100 -> 86.482394 | P14: =P6/P6*100 -> 100

Sheet HMA HR REVNUE SHEET
A1: Sl No | B1: HMA HR REVENUE | C1: 45407 | D1: 45772 | E1: 45437 | F1: 45802 | G1: 45468 | H1: 45833 | I1: 45474 | J1: 45839 | K1: 45505 | L1: 45870 | M1: 45536 | N1: 45901 | O1: 45566 | P1: 45931 | Q1: 45597 | R1: 45962 | S1: 45627 | T1: 45992 | U1: 45658 | V1: 46023 | W1: 45689 | X1: 46054 | Y1: 45717 | Z1: 46082
A2: 1 | B2: INTERNSHIP/ST INT | C2: =37760 -> 37760 | D2: =116230+15000 -> 131230 | E2: =132160+9440 -> 141600 | F2: 234230 | G2: 24190 | H2: 187620 | I2: 129210 | J2: 60000 | K2: 51520 | L2: 30680 | N2: 0 | Q2: =97070+32640 -> 129710 | S2: 10 | W2: 100300 | Y2: =111790+143823 -> 255613
A3: 2 | B3: TRAINING | C3: 23319 | D3: 258703 | E3: 38513 | G3: 133955 | H3: 60386 | I3: 23107 | J3: 0 | K3: 96659 | M3: 52380 | N3: 0 | O3: 23850 | S3: 534598 | U3: 18711 | W3: 170190 | Y3: 296964
A4: 3 | B4: RECRUITMENT | C4: 1928773 | D4: 263698 | F4: 19435 | H4: 161264 | L4: 393088 | N4: 0 | O4: 2014000 | S4: 3370919 | Y4: =93709+61803+3754+19329+2528189 -> 2706784
A5: 4 | B5: HALL RENT | N5: 0
A6: Total | C6: =SUM(C2:C5) -> 1989852 | D6: =SUM(D2:D5) -> 653631 | E6: =SUM(E2:E5) -> 180113 | F6: =SUM(F2:F5) -> 253665 | G6: =SUM(G2:G5) -> 158145 | H6: =SUM(H2:H5) -> 409270 | I6: =SUM(I2:I5) -> 152317 | J6: =SUM(J2:J5) -> 60000 | ... Z6: =SUM(Z2:Z5) -> 0
S8: KSBCDC-3370919 | Y8: KSBCDC-2528189

Sheet admin Sheet2
A1: LSGB | G1: JUNE
A2: 1 | B2: Manjith Travels | C2: Contract Vehicle | D2: Monthly | E2: 524160 | F2: =E2/12 -> 43680
A3: 5 | B3: Dr Anandam | C3: House Rent | D3: Monthly | E3: 1800000 | F3: =E3/12 -> 150000
A4: 8 | B4: BSNL | C4: Land Line | D4: Monthly | E4: 24000 | F4: =E4/12 -> 2000 | G4: admin
A5: 11 | B5: KSEB | C5: Electricity Bill | D5: Monthly | E5: 264000 | F5: =E5/12 -> 22000
A6: 12 | B6: KWA | C6: Water Bill | D6: Monthly | E6: 96000 | F6: =E6/12 -> 8000
A7: 14 | B7: Subramania Industries | C7: DG AMC | D7: Half Yearly | E7: 10000 | F7: =E7/12 -> 833.33333
A8: 13 | B8: Imprest | C8: Monthly Imprest | D8: Monthly | E8: 120000 | F8: =E8/12 -> 10000
A9: 15 | B9: Alchemy IBS | C9: Website | D9: Monthly | E9: 200000 | F9: =E9/12 -> 16666.667
A10: 16 | B10: Geejey Solutions | C10: Epabx AMC | D10: Half Yearly | E10: 8000 | F10: =E10/12 -> 666.66667
A11: 17 | B11: VRS infosystems | C11: Tally Software Renewal | D11: Annualy | E11: 16000 | F11: =E11/12 -> 1333.3333
A12: 18 | B12: M/sArmtech Computer Services | C12: CAMC computer hardware | D12: Quarterly | E12: 15000 | F12: =E12/12 -> 1250
A13: 19 | B13: Nu aire | C13: AC AMC | D13: Quarterly | E13: 36000 | F13: =E13/12 -> 3000
A14: 20 | B14: Miscellaneous | C14: Repair & Maintenance | D14: Monthly | E14: 50000 | F14: =E14/12 -> 4166.6667
A15: 21 | B15: Microsoft 365 | C15: Software | D15: Annualy | E15: 7000 | F15: =E15/12 -> 583.33333
A16: 2 | B16: Asterisk | C16: Photocopier (Admin & DVP) | D16: Monthly | E16: 48000 | F16: =E16/12 -> 4000
A17: 9 | B17: Pradeep Kumar Cost Accountant | C17: Financial Consultant | D17: Monthly | E17: 1296000 | F17: =E17/12 -> 108000
A18: 10 | B18: Pradeep Kumar Cost Accountant | C18: Accounts Assistance | D18: Monthly | E18: 750000 | F18: =E18/12 -> 62500 | I18: PROJECT 1
A19: 7 | B19: Indian Postal Department | C19: Speed post | D19: Monthly | E19: 120000 | F19: =E19/12 -> 10000 | H19: HR 5% OF CSR | I19: 29545
G20: 520400 | H20: ADMIN CHARGES CSR | I20: 29545
A21: =SUM(F1:F27) -> 580746 | H21: HMA HR REVENUE
A22: HR 5% OF CSR | G22: project-1 | H22: project-2 | I22: project-3
A23: 1 | B23: Manjith Travels | C23: Contract Vehicle | D23: Monthly | E23: 524160 | F23: =E23/12 -> 43680 | G23: =G29*F23/F29 -> 8676.8134
A24: 3 | B24: Oval Blue Technologies | C24: Photocopier SDP | D24: Monthly | E24: 84000 | F24: =E24/12 -> 7000 | G24: =G29*F24/F29 -> 1390.515
A25: 4 | B25: Volks Electronics | C25: Desktop rental | D25: Monthly | E25: 720000 | F25: =E25/12 -> 60000 | G25: =G29*F25/F29 -> 11918.7
A26: 6 | B26: Asianet | C26: Internet Services | D26: Quarterly | E26: 56640 | F26: =E26/12 -> 4720 | G26: =F26*G29/F29 -> 937.60438
B27: Stationary | C27: project documentation | E27: 200000 | F27: 16666 | G27: =F27*G29/F29 -> 3310.6175
A28: 15 | B28: Alchemy IBS | C28: Website | D28: Monthly | E28: 200000 | F28: =E28/12 -> 16666.667 | G28: =F28*G29/F29 -> 3310.7499
F29: =SUM(F23:F28) -> 148732.67 | G29: 29545
A30: Admin Expenses OF CSR @ 5%
A31: 1 | B31: Manjith Travels | C31: Contract Vehicle | D31: Monthly | E31: 524160 | F31: =E31/12 -> 43680
A32: 5 | B32: Dr Anandam | C32: House Rent | D32: Monthly | E32: 1800000 | F32: =E32/12 -> 150000
A33: 8 | B33: BSNL | C33: Land Line | D33: Monthly | E33: 24000 | F33: =E33/12 -> 2000
A34: 11 | B34: KSEB | C34: Electricity Bill | D34: Monthly | E34: 264000 | F34: =E34/12 -> 22000
A35: 12 | B35: KWA | C35: Water Bill | D35: Monthly | E35: 96000 | F35: =E35/12 -> 8000
A36: 14 | B36: Subramania Industries | C36: DG AMC | D36: Half Yearly | E36: 10000 | F36: =E36/12 -> 833.33333
A37: 13 | B37: Imprest | C37: Monthly Imprest | D37: Monthly | E37: 120000 | F37: =E37/12 -> 10000
A38: 15 | B38: Alchemy IBS | C38: Website | D38: Monthly | E38: 200000 | F38: =E38/12 -> 16666.667
A39: 16 | B39: Geejey Solutions | C39: Epabx AMC | D39: Half Yearly | E39: 8000 | F39: =E39/12 -> 666.66667
A40: 17 | B40: VRS infosystems | C40: Tally Software Renewal | D40: Annualy | E40: 16000 | F40: =E40/12 -> 1333.3333
...

Sheet admin Sheet3
A1: 682066 | B1: Project 1 | C1: Project 2 | D1: Project 3 | E1: Project 4 | F1: Project 5 | G1: Project 6 | H1: Total | K1: HMA HR REVENUE
A2: 5% of project | B2: 30000 | C2: 30000 | D2: 30000 | H2: =SUM(B2:G2) -> 90000 | J2: OB | K2: 2500000
A3: Total admin charges monthly actual reciept basis | B3: 20000 | C3: 10000 | D3: 3000 | H3: =SUM(B3:G3) -> 33000 | J3: internship | K3: 100000
A4: Total monthly HR revenue | H4: =K7 -> 165000 | J4: training | K4: 0
A5: balance lsgb | J5: recruitment | K5: 50000
J6: hall rent | K6: 15000
J7: TOTAL | K7: =SUM(K3:K6) -> 165000
K9: PROJECT ADMIN CHARGES
A10: Every month the expenses will be booked for the reciept amount and any balance amount if any shall be booked from lsgb | J10: OB | K10: 1500000
I11: JULY | J11: RECEIVED | K11: 33000
J13: TOTAL | K13: =SUM(K10:K12) -> 1533000
J14: 5% OF TOTAL | K14: =K13*5% -> 76650

Sheet responsiblity
A1: Master sheets | B1: Status | C1: Responsiblity
A2: Core team member Sheet | B2: completed | C2: Nikhil
A3: Sheet Updation | C3: Anakha Joy/Vishnu
A4: Cross Verify | C4: Nikhil
A5: Consolidated Sheet | C5: Nikhil
A6: Over view | C6: Nikhil /Savitha
A7: Project Wise Financial | C7: Arjuna/Rasna
A8: Project Wise Financial cross verify | C8: Arathy
A10: PROJECT SPECIFIC STAFF
A11: Project specific sheet | B11: completed | C11: Nikhil
A12: Sheet Updation | C12: Anakha Joy/Vishnu
A13: Cross Verify | C13: Nikhil
A14: Consolidated Sheet | C14: Nikhil
A17: CSR @ 5%

Sheet MANPOWER
F1: 45748 | H1: 45778 | K1: 45809 | M1: 45839 | O1: 45870 | Q1: 45901 | S1: 45931 | U1: 45962 | W1: 45992 | Y1: 46023 | AA1: 46054 | AC1: 46082
A2: SL No | B2: Name | C2: Designation | D2: Project | E2: Monthly CTC | F2: Attendance | G2: Amount | H2: Attendance2 | I2: Amount3 | J2: Amount4 | K2: Attendance3 | L2: Amount2 | M2: Attendance6 | N2: Amount7 | O2: Attendance8 | P2: Amount9 | Q2: Attendance10 | R2: Amount11 | S2: Attendance12 | T2: Amount13 | U2: Attendance14 | V2: Amount15 | W2: Attendance16 | X2: Amount17 | Y2: Attendance18 | Z2: Amount19 | AA2: Attendance20 | AB2: Amount21 | AC2: Attendance22 | AD2: Amount23
A3: 6 | B3: Gayatri Vijay L | C3: Field Assistant | D3: CORE TEAM | E3: 21367 | F3: 28 | G3: =MANPOWER!$E3/30*MANPOWER!$F3 -> 19942.533 | H3: 29 | I3: =MANPOWER!$E3/31*MANPOWER!$H3 -> 19988.484 | J3: =MANPOWER!$E3-MANPOWER!$I3 -> 1378.5161 | L3: =MANPOWER!$E$3:$E$56 -> 21367 | N3: =MANPOWER!$E$3:$E$56 -> 21367 | P3: =MANPOWER!$E$3:$E$56 -> 21367 | R3: =MANPOWER!$E$3:$E$56 -> 21367 | T3: =MANPOWER!$E$3:$E$56 -> 21367 | V3: =MANPOWER!$E$3:$E$56 -> 21367 | X3: =MANPOWER!$E$3:$E$56 -> 21367 | Z3: =MANPOWER!$E$3:$E$56 -> 21367 | AB3: =MANPOWER!$E$3:$E$56 -> 21367 | AD3: =MANPOWER!$E$3:$E$56 -> 21367
A4: 43 | B4: Vishnu | C4: Field Assistant | D4: LSGB | E4: 21367 | F4: 0 | G4: =MANPOWER!$E4/30*MANPOWER!$F4 -> 0 | H4: 19 | I4: =MANPOWER!$E4/31*MANPOWER!$H4 -> 13095.903 | J4: =MANPOWER!$E4-MANPOWER!$I4 -> 8271.0968 | L4: =MANPOWER!$E$3:$E$56 -> 21367 | N4: =MANPOWER!$E$3:$E$56 -> 21367 | P4: =MANPOWER!$E$3:$E$56 -> 21367 | R4: =MANPOWER!$E$3:$E$56 -> 21367 | T4: =MANPOWER!$E$3:$E$56 -> 21367 | V4: =MANPOWER!$E$3:$E$56 -> 21367 | X4: =MANPOWER!$E$3:$E$56 -> 21367 | Z4: =MANPOWER!$E$3:$E$56 -> 21367 | AB4: =MANPOWER!$E$3:$E$56 -> 21367 | AD4: =MANPOWER!$E$3:$E$56 -> 21367
A5: 49 | B5: Anakha Joy | C5: Field Assistant | E5: 21367 | F5: 0 | G5: =MANPOWER!$E5/30*MANPOWER!$F5 -> 0 | H5: 0 | I5: =MANPOWER!$E5/31*MANPOWER!$H5 -> 0 | J5: =MANPOWER!$E5-MANPOWER!$I5 -> 21367 | L5: =MANPOWER!$E$3:$E$56 -> 21367 | N5: =MANPOWER!$E$3:$E$56 -> 21367 | P5: =MANPOWER!$E$3:$E$56 -> 21367 | R5: =MANPOWER!$E$3:$E$56 -> 21367 | T5: =MANPOWER!$E$3:$E$56 -> 21367 | V5: =MANPOWER!$E$3:$E$56 -> 21367 | X5: =MANPOWER!$E$3:$E$56 -> 21367 | Z5: =MANPOWER!$E$3:$E$56 -> 21367 | AB5: =MANPOWER!$E$3:$E$56 -> 21367 | AD5: =MANPOWER!$E$3:$E$56 -> 21367
A6: 37 | B6: Jeena Raju | C6: Cleaning staff | D6: HLL My city | E6: 22348 | F6: 27 | G6: 22348 | H6: 25 | I6: 21488 | J6: =MANPOWER!$E6-MANPOWER!$I6 -> 860 | L6: =MANPOWER!$E$3:$E$56 -> 22348 | N6: =MANPOWER!$E$3:$E$56 -> 22348 | P6: =MANPOWER!$E$3:$E$56 -> 22348 | R6: =MANPOWER!$E$3:$E$56 -> 22348 | T6: =MANPOWER!$E$3:$E$56 -> 22348 | V6: =MANPOWER!$E$3:$E$56 -> 22348 | X6: =MANPOWER!$E$3:$E$56 -> 22348 | Z6: =MANPOWER!$E$3:$E$56 -> 22348 | AB6: =MANPOWER!$E$3:$E$56 -> 22348 | AD6: =MANPOWER!$E$3:$E$56 -> 22348
A7: 38 | B7: Sujitha S | C7: Cleaning staff | D7: HLL My city | E7: 22348 | F7: 20 | G7: 17191 | H7: 24 | I7: 20629 | J7: =MANPOWER!$E7-MANPOWER!$I7 -> 1719 | L7: =MANPOWER!$E$3:$E$56 -> 22348 | N7: =MANPOWER!$E$3:$E$56 -> 22348 | P7: =MANPOWER!$E$3:$E$56 -> 22348 | R7: =MANPOWER!$E$3:$E$56 -> 22348 | T7: =MANPOWER!$E$3:$E$56 -> 22348 | V7: =MANPOWER!$E$3:$E$56 -> 22348 | X7: =MANPOWER!$E$3:$E$56 -> 22348 | Z7: =MANPOWER!$E$3:$E$56 -> 22348 | AB7: =MANPOWER!$E$3:$E$56 -> 22348 | AD7: =MANPOWER!$E$3:$E$56 -> 22348
A8: 39 | B8: Sudheesh | C8: Cleaning staff | D8: HLL My city | E8: 22348 | F8: 19 | G8: 16331 | H8: 0 | I8: =MANPOWER!$E8/31*MANPOWER!$H8 -> 0 | J8: =MANPOWER!$E8-MANPOWER!$I8 -> 22348
B9: Sukumaran | C9: Cleaning staff | D9: HLL My city | E9: 22348 | F9: 0 | G9: =MANPOWER!$E9/30*MANPOWER!$F9 -> 0 | H9: 18 | I9: 15472 | J9: =MANPOWER!$E9-MANPOWER!$I9 -> 6876 | L9: =MANPOWER!$E$3:$E$56 -> 22348 | N9: =MANPOWER!$E$3:$E$56 -> 22348 | P9: =MANPOWER!$E$3:$E$56 -> 22348 | R9: =MANPOWER!$E$3:$E$56 -> 22348 | T9: =MANPOWER!$E$3:$E$56 -> 22348 | V9: =MANPOWER!$E$3:$E$56 -> 22348 | X9: =MANPOWER!$E$3:$E$56 -> 22348 | Z9: =MANPOWER!$E$3:$E$56 -> 22348 | AB9: =MANPOWER!$E$3:$E$56 -> 22348 | AD9: =MANPOWER!$E$3:$E$56 -> 22348
A10: 5 | B10: Soumya S K | C10: Field Assistant | D10: CORE TEAM | E10: 22689 | F10: 28.5 | G10: =MANPOWER!$E10/30*MANPOWER!$F10 -> 21554.55 | H10: 30 | I10: =MANPOWER!$E10/31*MANPOWER!$H10 -> 21957.097 | J10: =MANPOWER!$E10-MANPOWER!$I10 -> 731.90323 | L10: =MANPOWER!$E$3:$E$56 -> 22689 | N10: =MANPOWER!$E$3:$E$56 -> 22689 | P10: =MANPOWER!$E$3:$E$56 -> 22689 | R10: =MANPOWER!$E$3:$E$56 -> 22689 | T10: =MANPOWER!$E$3:$E$56 -> 22689 | V10: =MANPOWER!$E$3:$E$56 -> 22689 | X10: =MANPOWER!$E$3:$E$56 -> 22689 | Z10: =MANPOWER!$E$3:$E$56 -> 22689 | AB10: =MANPOWER!$E$3:$E$56 -> 22689 | AD10: =MANPOWER!$E$3:$E$56 -> 22689
A11: 7 | B11: Vignesh Kumar P B | C11: Office Assistant | D11: CORE TEAM | E11: 22689 | F11: 30 | G11: =MANPOWER!$E11/30*MANPOWER!$F11 -> 22689 | H11: 31 | I11: =MANPOWER!$E11/31*MANPOWER!$H11 -> 22689 | J11: =MANPOWER!$E11-MANPOWER!$I11 -> 0 | L11: =MANPOWER!$E$3:$E$56 -> 22689 | N11: =MANPOWER!$E$3:$E$56 -> 22689 | P11: =MANPOWER!$E$3:$E$56 -> 22689 | R11: =MANPOWER!$E$3:$E$56 -> 22689 | T11: =MANPOWER!$E$3:$E$56 -> 22689 | V11: =MANPOWER!$E$3:$E$56 -> 22689 | X11: =MANPOWER!$E$3:$E$56 -> 22689 | Z11: =MANPOWER!$E$3:$E$56 -> 22689 | AB11: =MANPOWER!$E$3:$E$56 -> 22689 | AD11: =MANPOWER!$E$3:$E$56 -> 22689
A12: 3 | B12: Ashitha Vins V M | C12: Backend Support | D12: CORE TEAM | E12: 23309 | F12: 30 | G12: =MANPOWER!$E12/30*MANPOWER!$F12 -> 23309 | H12: 31 | I12: =MANPOWER!$E12/31*MANPOWER!$H12 -> 23309 | J12: =MANPOWER!$E12-MANPOWER!$I12 -> 0 | L12: =MANPOWER!$E$3:$E$56 -> 23309 | N12: =MANPOWER!$E$3:$E$56 -> 23309 | P12: =MANPOWER!$E$3:$E$56 -> 23309 | R12: =MANPOWER!$E$3:$E$56 -> 23309 | T12: =MANPOWER!$E$3:$E$56 -> 23309 | V12: =MANPOWER!$E$3:$E$56 -> 23309 | X12: =MANPOWER!$E$3:$E$56 -> 23309 | Z12: =MANPOWER!$E$3:$E$56 -> 23309 | AB12: =MANPOWER!$E$3:$E$56 -> 23309 | AD12: =MANPOWER!$E$3:$E$56 -> 23309
A13: 4 | B13: Savitha Y | C13: Backend Support | D13: CORE TEAM | E13: 23309 | F13: 30 | G13: =MANPOWER!$E13/30*MANPOWER!$F13 -> 23309 | H13: 31 | I13: =MANPOWER!$E13/31*MANPOWER!$H13 -> 23309 | J13: =MANPOWER!$E13-MANPOWER!$I13 -> 0 | L13: =MANPOWER!$E$3:$E$56 -> 23309 | N13: =MANPOWER!$E$3:$E$56 -> 23309 | P13: =MANPOWER!$E$3:$E$56 -> 23309 | R13: =MANPOWER!$E$3:$E$56 -> 23309 | T13: =MANPOWER!$E$3:$E$56 -> 23309 | V13: =MANPOWER!$E$3:$E$56 -> 23309 | X13: =MANPOWER!$E$3:$E$56 -> 23309 | Z13: =MANPOWER!$E$3:$E$56 -> 23309 | AB13: =MANPOWER!$E$3:$E$56 -> 23309 | AD13: =MANPOWER!$E$3:$E$56 -> 23309
A14: 41 | B14: Silpa | C14: Accounts Assistant | D14: Finance | E14: 24508 | F14: 10 | G14: =MANPOWER!$E14/30*MANPOWER!$F14 -> 8169.3333 | H14: 30 | I14: =MANPOWER!$E14/31*MANPOWER!$H14 -> 23717.419 | J14: =MANPOWER!$E14-MANPOWER!$I14 -> 790.58065 | L14: =MANPOWER!$E$3:$E$56 -> 24508 | N14: =MANPOWER!$E$3:$E$56 -> 24508 | P14: =MANPOWER!$E$3:$E$56 -> 24508 | R14: =MANPOWER!$E$3:$E$56 -> 24508 | T14: =MANPOWER!$E$3:$E$56 -> 24508 | V14: =MANPOWER!$E$3:$E$56 -> 24508 | X14: =MANPOWER!$E$3:$E$56 -> 24508 | Z14: =MANPOWER!$E$3:$E$56 -> 24508 | AB14: =MANPOWER!$E$3:$E$56 -> 24508 | AD14: =MANPOWER!$E$3:$E$56 -> 24508
A15: 44 | B15: Preethima | C15: Project Assistant | D15: CSL, Andaman | E15: 24508 | F15: 0 | G15: =MANPOWER!$E15/30*MANPOWER!$F15 -> 0 | H15: 0 | I15: =MANPOWER!$E15/31*MANPOWER!$H15 -> 0 | J15: =MANPOWER!$E15-MANPOWER!$I15 -> 24508 | L15: =MANPOWER!$E$3:$E$56 -> 24508 | N15: =MANPOWER!$E$3:$E$56 -> 24508 | P15: =MANPOWER!$E$3:$E$56 -> 24508 | R15: =MANPOWER!$E$3:$E$56 -> 24508 | T15: =MANPOWER!$E$3:$E$56 -> 24508 | V15: =MANPOWER!$E$3:$E$56 -> 24508 | X15: =MANPOWER!$E$3:$E$56 -> 24508 | Z15: =MANPOWER!$E$3:$E$56 -> 24508 | AB15: =MANPOWER!$E$3:$E$56 -> 24508 | AD15: =MANPOWER!$E$3:$E$56 -> 24508
A16: 48 | B16: Sakshi Baliram Savare | C16: Project Assistant | D16: HLL CSR MAHARASHTRA | E16: 24508 | F16: 0 | G16: =MANPOWER!$E16/30*MANPOWER!$F16 -> 0 | H16: 6 | I16: =MANPOWER!$E16/31*MANPOWER!$H16 -> 4743.4839 | J16: =MANPOWER!$E16-MANPOWER!$I16 -> 19764.516 | L16: =MANPOWER!$E$3:$E$56 -> 24508 | N16: =MANPOWER!$E$3:$E$56 -> 24508 | P16: =MANPOWER!$E$3:$E$56 -> 24508 | R16: =MANPOWER!$E$3:$E$56 -> 24508 | T16: =MANPOWER!$E$3:$E$56 -> 24508 | V16: =MANPOWER!$E$3:$E$56 -> 24508 | X16: =MANPOWER!$E$3:$E$56 -> 24508 | Z16: =MANPOWER!$E$3:$E$56 -> 24508 | AB16: =MANPOWER!$E$3:$E$56 -> 24508 | AD16: =MANPOWER!$E$3:$E$56 -> 24508
A17: 50 | B17: Rakhee | C17: Project Assistant | D17: CSL, Andaman | E17: 24508 | F17: 0 | G17: =MANPOWER!$E17/30*MANPOWER!$F17 -> 0 | H17: 0 | I17: =MANPOWER!$E17/31*MANPOWER!$H17 -> 0 | J17: =MANPOWER!$E17-MANPOWER!$I17 -> 24508 | L17: =MANPOWER!$E$3:$E$56 -> 24508 | N17: =MANPOWER!$E$3:$E$56 -> 24508 | P17: =MANPOWER!$E$3:$E$56 -> 24508 | R17: =MANPOWER!$E$3:$E$56 -> 24508 | T17: =MANPOWER!$E$3:$E$56 -> 24508 | V17: =MANPOWER!$E$3:$E$56 -> 24508 | X17: =MANPOWER!$E$3:$E$56 -> 24508 | Z17: =MANPOWER!$E$3:$E$56 -> 24508 | AB17: =MANPOWER!$E$3:$E$56 -> 24508 | AD17: =MANPOWER!$E$3:$E$56 -> 24508
A18: 11 | B18: Jayalekshmi J | C18: Project Assistant | D18: LSGB | E18: 24509 | F18: 30 | G18: =MANPOWER!$E18/30*MANPOWER!$F18 -> 24509 | H18: 31 | I18: =MANPOWER!$E18/31*MANPOWER!$H18 -> 24509 | J18: =MANPOWER!$E18-MANPOWER!$I18 -> 0 | L18: =MANPOWER!$E$3:$E$56 -> 24509 | N18: =MANPOWER!$E$3:$E$56 -> 24509 | P18: =MANPOWER!$E$3:$E$56 -> 24509 | R18: =MANPOWER!$E$3:$E$56 -> 24509 | T18: =MANPOWER!$E$3:$E$56 -> 24509 | V18: =MANPOWER!$E$3:$E$56 -> 24509 | X18: =MANPOWER!$E$3:$E$56 -> 24509 | Z18: =MANPOWER!$E$3:$E$56 -> 24509 | AB18: =MANPOWER!$E$3:$E$56 -> 24509 | AD18: =MANPOWER!$E$3:$E$56 -> 24509
A19: 10 | B19: Sushila | C19: Project Assistant | D19: IOCL Panipat , Haryana | E19: 24523 | F19: 30 | G19: =MANPOWER!$E19/30*MANPOWER!$F19 -> 24523 | H19: 31 | I19: =MANPOWER!$E19/31*MANPOWER!$H19 -> 24523 | J19: =MANPOWER!$E19-MANPOWER!$I19 -> 0 | L19: =MANPOWER!$E$3:$E$56 -> 24523 | N19: =MANPOWER!$E$3:$E$56 -> 24523 | P19: =MANPOWER!$E$3:$E$56 -> 24523 | R19: =MANPOWER!$E$3:$E$56 -> 24523 | T19: =MANPOWER!$E$3:$E$56 -> 24523 | V19: =MANPOWER!$E$3:$E$56 -> 24523 | X19: =MANPOWER!$E$3:$E$56 -> 24523 | Z19: =MANPOWER!$E$3:$E$56 -> 24523 | AB19: =MANPOWER!$E$3:$E$56 -> 24523 | AD19: =MANPOWER!$E$3:$E$56 -> 24523
A20: 40 | B20: Syamili | C20: Admistrative Assistant (Projects) | D20: Consultancy Projects | E20: 25317 | F20: 24 | G20: =MANPOWER!$E20/30*MANPOWER!$F20 -> 20253.6 | H20: 31 | I20: =MANPOWER!$E20/31*MANPOWER!$H20 -> 25317 | J20: =MANPOWER!$E20-MANPOWER!$I20 -> 0 | L20: =MANPOWER!$E$3:$E$56 -> 25317 | N20: =MANPOWER!$E$3:$E$56 -> 25317 | P20: =MANPOWER!$E$3:$E$56 -> 25317 | R20: =MANPOWER!$E$3:$E$56 -> 25317 | T20: =MANPOWER!$E$3:$E$56 -> 25317 | V20: =MANPOWER!$E$3:$E$56 -> 25317 | X20: =MANPOWER!$E$3:$E$56 -> 25317 | Z20: =MANPOWER!$E$3:$E$56 -> 25317 | AB20: =MANPOWER!$E$3:$E$56 -> 25317 | AD20: =MANPOWER!$E$3:$E$56 -> 25317
A21: 8 | B21: Saidali Safar | C21: Procurement Assistant | D21: CORE TEAM | E21: 25318 | F21: 30 | G21: =MANPOWER!$E21/30*MANPOWER!$F21 -> 25318 | H21: 31 | I21: =MANPOWER!$E21/31*MANPOWER!$H21 -> 25318 | J21: =MANPOWER!$E21-MANPOWER!$I21 -> 0 | L21: =MANPOWER!$E$3:$E$56 -> 25318 | N21: =MANPOWER!$E$3:$E$56 -> 25318 | P21: =MANPOWER!$E$3:$E$56 -> 25318 | R21: =MANPOWER!$E$3:$E$56 -> 25318 | T21: =MANPOWER!$E$3:$E$56 -> 25318 | V21: =MANPOWER!$E$3:$E$56 -> 25318 | X21: =MANPOWER!$E$3:$E$56 -> 25318 | Z21: =MANPOWER!$E$3:$E$56 -> 25318 | AB21: =MANPOWER!$E$3:$E$56 -> 25318 | AD21: =MANPOWER!$E$3:$E$56 -> 25318
... A23: 9 | B23: Dhanya B L | C23: Project Assistant | D23: LSGB | E23: 26026 | F23: 28 | G23: =MANPOWER!$E23/30*MANPOWER!$F23 -> 24290.933 | H23: 30.5 | I23: =MANPOWER!$E23/31*MANPOWER!$H23 -> 25606.226 | J23: =MANPOWER!$E23-MANPOWER!$I23 -> 419.77419 | L23: =MANPOWER!$E$3:$E$56 -> 26026 | N23: =MANPOWER!$E$3:$E$56 -> 26026 | P23: =MANPOWER!$E$3:$E$56 -> 26026 | R23: =MANPOWER!$E$3:$E$56 -> 26026 | T23: =MANPOWER!$E$3:$E$56 -> 26026 | V23: =MANPOWER!$E$3:$E$56 -> 26026 | X23: =MANPOWER!$E$3:$E$56 -> 26026 | Z23: =MANPOWER!$E$3:$E$56 -> 26026 | AB23: =MANPOWER!$E$3:$E$56 -> 26026 | AD23: =MANPOWER!$E$3:$E$56 -> 26026
A24: 1 | B24: Heksy Sebastian | C24: Admistrative Assistant (Projects) | D24: CORE TEAM | E24: 26885 | F24: 27.5 | G24: =MANPOWER!$E24/30*MANPOWER!$F24 -> 24644.583 | H24: 24.5 | I24: =MANPOWER!$E24/31*MANPOWER!$H24 -> 21247.823 | J24: =MANPOWER!$E24-MANPOWER!$I24 -> 5637.1774 | L24: 26885 | N24: =MANPOWER!$E$3:$E$56 -> 26885 | P24: =MANPOWER!$E$3:$E$56 -> 26885 | R24: =MANPOWER!$E$3:$E$56 -> 26885 | T24: =MANPOWER!$E$3:$E$56 -> 26885 | V24: =MANPOWER!$E$3:$E$56 -> 26885 | X24: =MANPOWER!$E$3:$E$56 -> 26885 | Z24: =MANPOWER!$E$3:$E$56 -> 26885 | AB24: =MANPOWER!$E$3:$E$56 -> 26885 | AD24: =MANPOWER!$E$3:$E$56 -> 26885
A25: 2 | B25: Manjusha V | C25: Admistrative Assistant (Projects) | D25: CORE TEAM | E25: 26885 | F25: 30 | G25: =MANPOWER!$E25/30*MANPOWER!$F25 -> 26885 | H25: 30 | I25: =MANPOWER!$E25/31*MANPOWER!$H25 -> 26017.742 | J25: =MANPOWER!$E25-MANPOWER!$I25 -> 867.25806 | L25: =MANPOWER!$E$3:$E$56 -> 26885 | N25: =MANPOWER!$E$3:$E$56 -> 26885 | P25: =MANPOWER!$E$3:$E$56 -> 26885 | R25: =MANPOWER!$E$3:$E$56 -> 26885 | T25: =MANPOWER!$E$3:$E$56 -> 26885 | V25: =MANPOWER!$E$3:$E$56 -> 26885 | X25: =MANPOWER!$E$3:$E$56 -> 26885 | Z25: =MANPOWER!$E$3:$E$56 -> 26885 | AB25: =MANPOWER!$E$3:$E$56 -> 26885 | AD25: =MANPOWER!$E$3:$E$56 -> 26885
A26: 13 | B26: Mariyathul Hibthiya | C26: Project Associate | D26: IOCL LAKSWADEEP | E26: 30096 | F26: 30 | G26: =MANPOWER!$E26/30*MANPOWER!$F26 -> 30096 | H26: 31 | I26: =MANPOWER!$E26/31*MANPOWER!$H26 -> 30096 | J26: =MANPOWER!$E26-MANPOWER!$I26 -> 0 | L26: =MANPOWER!$E$3:$E$56 -> 30096 | N26: =MANPOWER!$E$3:$E$56 -> 30096 | P26: =MANPOWER!$E$3:$E$56 -> 30096 | R26: =MANPOWER!$E$3:$E$56 -> 30096 | T26: =MANPOWER!$E$3:$E$56 -> 30096 | V26: =MANPOWER!$E$3:$E$56 -> 30096 | X26: =MANPOWER!$E$3:$E$56 -> 30096 | Z26: =MANPOWER!$E$3:$E$56 -> 30096 | AB26: =MANPOWER!$E$3:$E$56 -> 30096 | AD26: =MANPOWER!$E$3:$E$56 -> 30096
A27: 14 | B27: Ruksana Beegum Pakkichippura | C27: Project Associate | D27: IOCL LAKSWADEEP | E27: 30096 | F27: 30 | G27: =MANPOWER!$E27/30*MANPOWER!$F27 -> 30096 | H27: 31 | I27: =MANPOWER!$E27/31*MANPOWER!$H27 -> 30096 | J27: =MANPOWER!$E27-MANPOWER!$I27 -> 0 | L27: =MANPOWER!$E$3:$E$56 -> 30096 | N27: =MANPOWER!$E$3:$E$56 -> 30096 | P27: =MANPOWER!$E$3:$E$56 -> 30096 | R27: =MANPOWER!$E$3:$E$56 -> 30096 | T27: =MANPOWER!$E$3:$E$56 -> 30096 | V27: =MANPOWER!$E$3:$E$56 -> 30096 | X27: =MANPOWER!$E$3:$E$56 -> 30096 | Z27: =MANPOWER!$E$3:$E$56 -> 30096 | AB27: =MANPOWER!$E$3:$E$56 -> 30096 | AD27: =MANPOWER!$E$3:$E$56 -> 30096
A28: 24 | B28: Greeshma Kuriakose | C28: Project Associate (Public Health) | D28: CPCL North Chennai | E28: 30096 | F28: 30 | G28: =MANPOWER!$E28/30*MANPOWER!$F28 -> 30096 | H28: 31 | I28: =MANPOWER!$E28/31*MANPOWER!$H28 -> 30096 | J28: =MANPOWER!$E28-MANPOWER!$I28 -> 0 | L28: =MANPOWER!$E$3:$E$56 -> 30096 | N28: =MANPOWER!$E$3:$E$56 -> 30096 | P28: =MANPOWER!$E$3:$E$56 -> 30096 | R28: =MANPOWER!$E$3:$E$56 -> 30096 | T28: =MANPOWER!$E$3:$E$56 -> 30096 | V28: =MANPOWER!$E$3:$E$56 -> 30096 | X28: =MANPOWER!$E$3:$E$56 -> 30096 | Z28: =MANPOWER!$E$3:$E$56 -> 30096 | AB28: =MANPOWER!$E$3:$E$56 -> 30096 | AD28: =MANPOWER!$E$3:$E$56 -> 30096
A29: 35 | B29: Ashwini Bhausaheb Ranjane | C29: Project Associate (Public Health) | D29: HLL CSR Maharashtra | E29: 30096 | F29: 30 | G29: =MANPOWER!$E29/30*MANPOWER!$F29 -> 30096 | H29: 31 | I29: =MANPOWER!$E29/31*MANPOWER!$H29 -> 30096 | J29: =MANPOWER!$E29-MANPOWER!$I29 -> 0 | L29: =MANPOWER!$E$3:$E$56 -> 30096 | N29: =MANPOWER!$E$3:$E$56 -> 30096 | P29: =MANPOWER!$E$3:$E$56 -> 30096 | R29: =MANPOWER!$E$3:$E$56 -> 30096 | T29: =MANPOWER!$E$3:$E$56 -> 30096 | V29: =MANPOWER!$E$3:$E$56 -> 30096 | X29: =MANPOWER!$E$3:$E$56 -> 30096 | Z29: =MANPOWER!$E$3:$E$56 -> 30096 | AB29: =MANPOWER!$E$3:$E$56 -> 30096 | AD29: =MANPOWER!$E$3:$E$56 -> 30096
A30: 22 | B30: Swathy Krishna S | C30: Project Associate (Community Development) | D30: HMA Communications | E30: 30156 | F30: 29.5 | G30: =MANPOWER!$E30/30*MANPOWER!$F30 -> 29653.4 | H30: 26 | I30: =MANPOWER!$E30/31*MANPOWER!$H30 -> 25292.129 | J30: =MANPOWER!$E30-MANPOWER!$I30 -> 4863.871 | L30: =MANPOWER!$E$3:$E$56 -> 30156 | N30: =MANPOWER!$E$3:$E$56 -> 30156 | P30: =MANPOWER!$E$3:$E$56 -> 30156 | R30: =MANPOWER!$E$3:$E$56 -> 30156 | T30: =MANPOWER!$E$3:$E$56 -> 30156 | V30: =MANPOWER!$E$3:$E$56 -> 30156 | X30: =MANPOWER!$E$3:$E$56 -> 30156 | Z30: =MANPOWER!$E$3:$E$56 -> 30156 | AB30: =MANPOWER!$E$3:$E$56 -> 30156 | AD30: =MANPOWER!$E$3:$E$56 -> 30156
A31: 34 | B31: Anjali Prakash K | C31: Project Associate (Public Health) | D31: LSGB | E31: 30156 | F31: 30 | G31: =MANPOWER!$E31/30*MANPOWER!$F31 -> 30156 | H31: 31 | I31: =MANPOWER!$E31/31*MANPOWER!$H31 -> 30156 | J31: =MANPOWER!$E31-MANPOWER!$I31 -> 0 | L31: =MANPOWER!$E$3:$E$56 -> 30156 | N31: =MANPOWER!$E$3:$E$56 -> 30156 | P31: =MANPOWER!$E$3:$E$56 -> 30156 | R31: =MANPOWER!$E$3:$E$56 -> 30156 | T31: =MANPOWER!$E$3:$E$56 -> 30156 | V31: =MANPOWER!$E$3:$E$56 -> 30156 | X31: =MANPOWER!$E$3:$E$56 -> 30156 | Z31: =MANPOWER!$E$3:$E$56 -> 30156 | AB31: =MANPOWER!$E$3:$E$56 -> 30156 | AD31: =MANPOWER!$E$3:$E$56 -> 30156
A32: 42 | B32: Ajila Mohan N J | C32: Project Associate | D32: HLL CSR Division | E32: 30156 | F32: 0 | G32: =MANPOWER!$E32/30*MANPOWER!$F32 -> 0 | H32: 20 | I32: =MANPOWER!$E32/31*MANPOWER!$H32 -> 19455.484 | J32: =MANPOWER!$E32-MANPOWER!$I32 -> 10700.516 | L32: =MANPOWER!$E$3:$E$56 -> 30156 | N32: =MANPOWER!$E$3:$E$56 -> 30156 | P32: =MANPOWER!$E$3:$E$56 -> 30156 | R32: =MANPOWER!$E$3:$E$56 -> 30156 | T32: =MANPOWER!$E$3:$E$56 -> 30156 | V32: =MANPOWER!$E$3:$E$56 -> 30156 | X32: =MANPOWER!$E$3:$E$56 -> 30156 | Z32: =MANPOWER!$E$3:$E$56 -> 30156 | AB32: =MANPOWER!$E$3:$E$56 -> 30156 | AD32: =MANPOWER!$E$3:$E$56 -> 30156
A33: 45 | B33: Elizabeth Packim | C33: Project Associate | D33: CSL, Andaman | E33: 30156 | F33: 0 | G33: =MANPOWER!$E33/30*MANPOWER!$F33 -> 0 | H33: 9 | I33: =MANPOWER!$E33/31*MANPOWER!$H33 -> 8754.9677 | J33: =MANPOWER!$E33-MANPOWER!$I33 -> 21401.032 | L33: =MANPOWER!$E$3:$E$56 -> 30156 | N33: =MANPOWER!$E$3:$E$56 -> 30156 | P33: =MANPOWER!$E$3:$E$56 -> 30156 | R33: =MANPOWER!$E$3:$E$56 -> 30156 | T33: =MANPOWER!$E$3:$E$56 -> 30156 | V33: =MANPOWER!$E$3:$E$56 -> 30156 | X33: =MANPOWER!$E$3:$E$56 -> 30156 | Z33: =MANPOWER!$E$3:$E$56 -> 30156 | AB33: =MANPOWER!$E$3:$E$56 -> 30156 | AD33: =MANPOWER!$E$3:$E$56 -> 30156
A34: 46 | B34: Arathy A S Kumar | C34: Project Associate | E34: 30156 | F34: 0 | G34: =MANPOWER!$E34/30*MANPOWER!$F34 -> 0 | H34: 11 | I34: =MANPOWER!$E34/31*MANPOWER!$H34 -> 10700.516 | J34: =MANPOWER!$E34-MANPOWER!$I34 -> 19455.484 | L34: =MANPOWER!$E$3:$E$56 -> 30156 | N34: =MANPOWER!$E$3:$E$56 -> 30156 | P34: =MANPOWER!$E$3:$E$56 -> 30156 | R34: =MANPOWER!$E$3:$E$56 -> 30156 | T34: =MANPOWER!$E$3:$E$56 -> 30156 | V34: =MANPOWER!$E$3:$E$56 -> 30156 | X34: =MANPOWER!$E$3:$E$56 -> 30156 | Z34: =MANPOWER!$E$3:$E$56 -> 30156 | AB34: =MANPOWER!$E$3:$E$56 -> 30156 | AD34: =MANPOWER!$E$3:$E$56 -> 30156
A35: 47 | B35: Juhaina C K | C35: Project Associate | D35: HLL CSR MALAPPURAM | E35: 30156 | F35: 0 | G35: =MANPOWER!$E35/30*MANPOWER!$F35 -> 0 | H35: 6 | I35: =MANPOWER!$E35/31*MANPOWER!$H35 -> 5836.6452 | J35: =MANPOWER!$E35-MANPOWER!$I35 -> 24319.355 | L35: =MANPOWER!$E$3:$E$56 -> 30156 | N35: =MANPOWER!$E$3:$E$56 -> 30156 | P35: =MANPOWER!$E$3:$E$56 -> 30156 | R35: =MANPOWER!$E$3:$E$56 -> 30156 | T35: =MANPOWER!$E$3:$E$56 -> 30156 | V35: =MANPOWER!$E$3:$E$56 -> 30156 | X35: =MANPOWER!$E$3:$E$56 -> 30156 | Z35: =MANPOWER!$E$3:$E$56 -> 30156 | AB35: =MANPOWER!$E$3:$E$56 -> 30156 | AD35: =MANPOWER!$E$3:$E$56 -> 30156
A36: 51 | B36: Navya M | C36: Project Associate | D36: Powergrid CSR Thinkal | E36: 30156 | F36: 0 | G36: =MANPOWER!$E36/30*MANPOWER!$F36 -> 0 | H36: 0 | I36: =MANPOWER!$E36/31*MANPOWER!$H36 -> 0 | J36: =MANPOWER!$E36-MANPOWER!$I36 -> 30156 | L36: =MANPOWER!$E$3:$E$56 -> 30156 | N36: =MANPOWER!$E$3:$E$56 -> 30156 | P36: =MANPOWER!$E$3:$E$56 -> 30156 | R36: =MANPOWER!$E$3:$E$56 -> 30156 | T36: =MANPOWER!$E$3:$E$56 -> 30156 | V36: =MANPOWER!$E$3:$E$56 -> 30156 | X36: =MANPOWER!$E$3:$E$56 -> 30156 | Z36: =MANPOWER!$E$3:$E$56 -> 30156 | AB36: =MANPOWER!$E$3:$E$56 -> 30156 | AD36: =MANPOWER!$E$3:$E$56 -> 30156
A37: 23 | B37: Alka Wadhwa | C37: Project Associate (Public Health) | D37: IOCL CSR Haryana | E37: 30156 | F37: 30 | G37: =MANPOWER!$E37/30*MANPOWER!$F37 -> 30156 | H37: 31 | I37: =MANPOWER!$E37/31*MANPOWER!$H37 -> 30156 | J37: =MANPOWER!$E37-MANPOWER!$I37 -> 0 | L37: =MANPOWER!$E$3:$E$56 -> 30156 | N37: =MANPOWER!$E$3:$E$56 -> 30156 | P37: =MANPOWER!$E$3:$E$56 -> 30156 | R37: =MANPOWER!$E$3:$E$56 -> 30156 | T37: =MANPOWER!$E$3:$E$56 -> 30156 | V37: =MANPOWER!$E$3:$E$56 -> 30156 | X37: =MANPOWER!$E$3:$E$56 -> 30156 | Z37: =MANPOWER!$E$3:$E$56 -> 30156 | AB37: =MANPOWER!$E$3:$E$56 -> 30156 | AD37: =MANPOWER!$E$3:$E$56 -> 30156
A38: 36 | B38: Anjaly V | C38: Project Facilitator | D38: CORE TEAM | E38: 30635 | F38: 30 | G38: =MANPOWER!$E38/30*MANPOWER!$F38 -> 30635 | H38: 31 | I38: =MANPOWER!$E38/31*MANPOWER!$H38 -> 30635 | J38: =MANPOWER!$E38-MANPOWER!$I38 -> 0 | L38: =MANPOWER!$E$3:$E$56 -> 30635 | N38: =MANPOWER!$E$3:$E$56 -> 30635 | P38: =MANPOWER!$E$3:$E$56 -> 30635 | R38: =MANPOWER!$E$3:$E$56 -> 30635 | T38: =MANPOWER!$E$3:$E$56 -> 30635 | V38: =MANPOWER!$E$3:$E$56 -> 30635 | X38: =MANPOWER!$E$3:$E$56 -> 30635 | Z38: =MANPOWER!$E$3:$E$56 -> 30635 | AB38: =MANPOWER!$E$3:$E$56 -> 30635 | AD38: =MANPOWER!$E$3:$E$56 -> 30635
A39: 20 | B39: Anjali A S | C39: Project Associate (Community Development) | D39: LSGB | E39: 31064 | F39: 30 | G39: =MANPOWER!$E39/30*MANPOWER!$F39 -> 31064 | H39: 31 | I39: =MANPOWER!$E39/31*MANPOWER!$H39 -> 31064 | J39: =MANPOWER!$E39-MANPOWER!$I39 -> 0 | L39: =MANPOWER!$E$3:$E$56 -> 31064 | N39: =MANPOWER!$E$3:$E$56 -> 31064 | P39: =MANPOWER!$E$3:$E$56 -> 31064 | R39: =MANPOWER!$E$3:$E$56 -> 31064 | T39: =MANPOWER!$E$3:$E$56 -> 31064 | V39: =MANPOWER!$E$3:$E$56 -> 31064 | X39: =MANPOWER!$E$3:$E$56 -> 31064 | Z39: =MANPOWER!$E$3:$E$56 -> 31064 | AB39: =MANPOWER!$E$3:$E$56 -> 31064 | AD39: =MANPOWER!$E$3:$E$56 -> 31064
A40: 21 | B40: Rakhi Mohan | C40: Project Associate (Community Development) | D40: LSGB | E40: 31064 | F40: 28 | G40: =MANPOWER!$E40/30*MANPOWER!$F40 -> 28993.067 | H40: 31 | I40: =MANPOWER!$E40/31*MANPOWER!$H40 -> 31064 | J40: =MANPOWER!$E40-MANPOWER!$I40 -> 0 | L40: =MANPOWER!$E$3:$E$56 -> 31064 | N40: =MANPOWER!$E$3:$E$56 -> 31064 | P40: =MANPOWER!$E$3:$E$56 -> 31064 | R40: =MANPOWER!$E$3:$E$56 -> 31064 | T40: =MANPOWER!$E$3:$E$56 -> 31064 | V40: =MANPOWER!$E$3:$E$56 -> 31064 | X40: =MANPOWER!$E$3:$E$56 -> 31064 | Z40: =MANPOWER!$E$3:$E$56 -> 31064 | AB40: =MANPOWER!$E$3:$E$56 -> 31064 | AD40: =MANPOWER!$E$3:$E$56 -> 31064
A41: 15 | B41: Abhirami N A | C41: Project Associate (Community Development) | D41: LSGB | E41: 31762 | F41: 25 | G41: =MANPOWER!$E41/30*MANPOWER!$F41 -> 26468.333 | H41: 24 | I41: =MANPOWER!$E41/31*MANPOWER!$H41 -> 24589.935 | J41: =MANPOWER!$E41-MANPOWER!$I41 -> 7172.0645 | L41: =MANPOWER!$E$3:$E$56 -> 31762 | N41: =MANPOWER!$E$3:$E$56 -> 31762 | P41: =MANPOWER!$E$3:$E$56 -> 31762 | R41: =MANPOWER!$E$3:$E$56 -> 31762 | T41: =MANPOWER!$E$3:$E$56 -> 31762 | V41: =MANPOWER!$E$3:$E$56 -> 31762 | X41: =MANPOWER!$E$3:$E$56 -> 31762 | Z41: =MANPOWER!$E$3:$E$56 -> 31762 | AB41: =MANPOWER!$E$3:$E$56 -> 31762 | AD41: =MANPOWER!$E$3:$E$56 -> 31762
...

Sheet PROJECT SHEET
A1: Consolidated Expense | L1: Project Manpower
A2: Month | B2: Project 1 | C2: Project 2 | D2: Project 3 | E2: Project 4 | F2: Project 5 | G2: Project 6 | H2: Project 7 | I2: LSGB | J2: Total | L2: Month | M2: Project 1 | N2: Project 2 | O2: Project 3 | P2: Project 4 | Q2: Project 5 | R2: Project 6 | S2: Project 7 | T2: LSGB | U2: Total
A3: 45839 | B3: =M3+B15+M15 -> 10701 | C3: =N3+C15+N15 -> 8838 | D3: =O3+D15+O15 -> 13560 | E3: =P3+E15+P15 -> 17030 | F3: =Q3+F15+Q15 -> 20038 | G3: =R3+G15+R15 -> 24030 | H3: =S3+H15+S15 -> 12772 | I3: =T3+I15+T15 -> 60226 | J3: =U3+J15+U15 -> 167195 | L3: 45839 | M3: 2550 | N3: 3600 | O3: 5000 | P3: 6800 | Q3: 9000 | R3: 12000 | S3: 3500 | T3: 45050 | U3: =SUM(M3:T3) -> 87500
A4: 45870 | L4: 45870
A5: 45901 | L5: 45901
A6: 45931 | L6: 45931
A7: 45962 | L7: 45962
A8: 45992 | L8: 45992
A9: 46023 | L9: 46023
A10: 46054 | L10: 46054
A11: 46082 | L11: 46082
A12: Total
A13: Admin Expenses | L13: Core Manpower
A14: Month | B14: Project 1 | C14: Project 2 | D14: Project 3 | E14: Project 4 | F14: Project 5 | G14: Project 6 | H14: Project 7 | I14: LSGB | J14: Total | L14: Month | M14: Project 1 | N14: Project 2 | O14: Project 3 | P14: Project 4 | Q14: Project 5 | R14: Project 6 | S14: Project 7 | T14: LSGB | U14: Total
A15: 45839 | B15: 5126 | C15: 1234 | D15: 3560 | E15: 7030 | F15: 6012 | G15: 1230 | H15: 6421 | I15: 1111 | J15: =SUM(B15:I15) -> 31724 | L15: 45839 | M15: 3025 | N15: 4004 | O15: 5000 | P15: 3200 | Q15: 5026 | R15: 10800 | S15: 2851 | T15: 14065 | U15: =SUM(M15:T15) -> 47971
A16: 45870 | L16: 45870
A17: 45901 | L17: 45901
A18: 45931 | L18: 45931
A19: 45962 | L19: 45962
A20: 45992 | L20: 45992
A21: 46023 | L21: 46023
A22: 46054 | L22: 46054
A23: 46082 | L23: 46082

Sheet Sheet2
C1: CSR | L1: Consultancy -VBD/HCS
A2: Month | C2: Project 1 | D2: Project 2 | E2: Project 3 | F2: Project 4 | G2: Project 5 | H2: Project 6 | I2: Project 7 | K2: ARREARS 2024-25 | L2: Project 1 | M2: Project 2 | N2: Project 3 | O2: Project 4 | P2: Project 5 | Q2: CSR +VBD TOTAL | R2: LSGB
A3: 45839 | B3: 587176 | C3: 29545 | D3: 29545 | E3: 29545 | K3: 0 | L3: 50000 | Q3: =SUM(C3:P3) -> 138635 | R3: =B3-C3-D3-E3-F3-G3-H3-K3-I3-L3-M3-N3-O3-P3 -> 448541
A4: 45870
A5: 45901
A6: 45931
A7: 45962
A8: 45992
A9: 46023
A10: 46054
A11: 46082
Q13: =Q3/B3*100 -> 23.610468 | R13: =R3/B3*100 -> 76.389532
F14: =B3/C3 -> 19.873955
B16: =B3/12 -> 48931.333 | I16: =20*65000000 -> 1300000000

Sheet Sheet3
A1: EMPLOYEE BENEFIT COST | D1: CSR | E1: HMA REVENUE | F1: LSGB | G1: VBD | H1: CORE
A2: TPC SALARY | B2: 14400000 | D2: 3051708 | F2: 5184240 | H2: =B2-D2-F2 -> 6164052
A3: FTC SALARY | B3: 2700000
A4: PERMANENT | B4: 4800000
B5: =SUM(B2:B4) -> 21900000

Sheet MASTER FILE
F1: 45748 | H1: 45778 | J1: 45809 | L1: 45839 | N1: 45870 | P1: 45901 | R1: 45931 | T1: 45962 | V1: 45992 | X1: 46023 | Z1: 46054 | AB1: 46082
A2: SL No | B2: Name | C2: Designation | D2: Project | E2: Monthly CTC | F2: Attendance | G2: Amount | H2: Attendance | I2: Amount | J2: Attendance | K2: Amount | L2: Attendance | M2: Amount | N2: Attendance | O2: Amount | P2: Attendance | Q2: Amount | R2: Attendance | S2: Amount | T2: Attendance | U2: Amount | V2: Attendance | W2: Amount | X2: Attendance | Y2: Amount | Z2: Attendance | AA2: Amount | AB2: Attendance | AC2: Amount | AD2: Month | AE2: Project 1 | AF2: Project 2 | AG2: Project 3 | AH2: Project 4 | AI2: Project 5 | AJ2: Project 6 | AK2: Project 7 | AL2: LSGB
A3: 1 | B3: Heksy Sebastian | C3: Admistrative Assistant (Projects) | D3: CORE TEAM | E3: 26885 | F3: 27.5 | G3: 24644.583 | H3: 24.5 | I3: 21247.823 | K3: 26885 | L3: =HEKSY!L37 -> 28.5 | M3: =HEKSY!M37 -> 25861.452 | N3: =HEKSY!N37 -> 29.5 | O3: =HEKSY!O37 -> 26768.871 | P3: =HEKSY!P37 -> 26 | Q3: =HEKSY!Q37 -> 24379.333 | R3: =HEKSY!R37 -> 28 | S3: =HEKSY!S37 -> 25407.742 | ... AC3: =HEKSY!AC37 -> 28130 | AD3: 45839
A4: 2 | B4: Manjusha V | C4: Admistrative Assistant (Projects) | D4: CORE TEAM | E4: 26885 | F4: 30 | G4: 26885 | H4: 30 | I4: 26017.742 | K4: 26885 | L4: =MANJUSHA!L37 -> 31 | M4: =MANJUSHA!M37 -> 27598 | N4: =MANJUSHA!N37 -> 31 | O4: =MANJUSHA!O37 -> 27598 | P4: =MANJUSHA!P37 -> 26 | Q4: =MANJUSHA!Q37 -> 23918.267 | R4: =MANJUSHA!R37 -> 26 | S4: =MANJUSHA!S37 -> 23146.71 | ... AC4: =MANJUSHA!AC37 -> 27598 | AD4: 45870
A5: 3 | B5: Ashitha Vins V M | C5: Backend Support | D5: CORE TEAM | E5: 23309 | F5: 30 | G5: 23309 | H5: 31 | I5: 23309 | K5: 23309 | M5: 23309 | O5: 23309 | Q5: 23309 | S5: 23309 | U5: 23309 | W5: 23309 | Y5: 23309 | AA5: 23309 | AC5: 23309 | AD5: 45901
A6: 4 | B6: Savitha Y | C6: Backend Support | D6: CORE TEAM | E6: 23309 | F6: 30 | G6: 23309 | H6: 31 | I6: 23309 | K6: 23309 | M6: 23309 | O6: 23309 | Q6: 23309 | S6: 23309 | U6: 23309 | W6: 23309 | Y6: 23309 | AA6: 23309 | AC6: 23309 | AD6: 45931
A7: 5 | B7: Soumya S K | C7: Field Assistant | D7: CORE TEAM | E7: 22689 | F7: 28.5 | G7: 21554.55 | H7: 30 | I7: 21957.097 | K7: 22689 | M7: 22689 | O7: 22689 | Q7: 22689 | S7: 22689 | U7: 22689 | W7: 22689 | Y7: 22689 | AA7: 22689 | AC7: 22689 | AD7: 45962
A8: 6 | B8: Gayatri Vijay L | C8: Field Assistant | D8: CORE TEAM | E8: 21367 | F8: 28 | G8: 19942.533 | H8: 29 | I8: 19988.484 | K8: 21367 | M8: 21367 | O8: 21367 | Q8: 21367 | S8: 21367 | U8: 21367 | W8: 21367 | Y8: 21367 | AA8: 21367 | AC8: 21367 | AD8: 45992
A9: 7 | B9: Vignesh Kumar P B | C9: Office Assistant | D9: CORE TEAM | E9: 22689 | F9: 30 | G9: 22689 | H9: 31 | I9: 22689 | K9: 22689 | M9: 22689 | O9: 22689 | Q9: 22689 | S9: 22689 | U9: 22689 | W9: 22689 | Y9: 22689 | AA9: 22689 | AC9: 22689 | AD9: 46023
A10: 8 | B10: Saidali Safar | C10: Procurement Assistant | D10: CORE TEAM | E10: 25318 | F10: 30 | G10: 25318 | H10: 31 | I10: 25318 | K10: 25318 | M10: 25318 | O10: 25318 | Q10: 25318 | S10: 25318 | U10: 25318 | W10: 25318 | Y10: 25318 | AA10: 25318 | AC10: 25318 | AD10: 46054
A11: 9 | B11: Dhanya B L | C11: Project Assistant | D11: CORE TEAM | E11: 26026 | F11: 28 | G11: 24290.933 | H11: 30.5 | I11: 25606.226 | K11: 26026 | M11: 26026 | O11: 26026 | Q11: 26026 | S11: 26026 | U11: 26026 | W11: 26026 | Y11: 26026 | AA11: 26026 | AC11: 26026 | AD11: 46082
A12: 10 | B12: Sushila | C12: Project Assistant | D12: IOCL CSR HARYANA | E12: 24523 | F12: 30 | G12: 24523 | H12: 31 | I12: 24523 | K12: 24523 | M12: 24523 | O12: 24523 | Q12: 24523 | S12: 24523 | U12: 24523 | W12: 24523 | Y12: 24523 | AA12: 24523 | AC12: 24523
A13: 11 | B13: Jayalekshmi J | C13: Project Assistant | D13: LSGB | E13: 24509 | F13: 30 | G13: 24509 | H13: 31 | I13: 24509 | K13: 24509 | M13: 24509 | O13: 24509 | Q13: 24509 | S13: 24509 | U13: 24509 | W13: 24509 | Y13: 24509 | AA13: 24509 | AC13: 24509
A14: 12 | B14: Titu S Jayan | C14: Project Assistant (Accounts) | D14: CORE TEAM | E14: 25802 | F14: 30 | G14: 25802 | H14: 29.5 | I14: 24553.516 | K14: 25802 | M14: 25802 | O14: 25802 | Q14: 25802 | S14: 25802 | U14: 25802 | W14: 25802 | Y14: 25802 | AA14: 25802 | AC14: 25802
A15: 13 | B15: Mariyathul Hibthiya | C15: Project Associate | D15: IOCL LAKSWADEEP | E15: 30096 | F15: 30 | G15: 30096 | H15: 31 | I15: 30096 | K15: 30096 | M15: 30096 | O15: 30096 | Q15: 30096 | S15: 30096 | U15: 30096 | W15: 30096 | Y15: 30096 | AA15: 30096 | AC15: 30096
A16: 14 | B16: Ruksana Beegum Pakkichippura | C16: Project Associate | D16: IOCL LAKSWADEEP | E16: 30096 | F16: 30 | G16: 30096 | H16: 31 | I16: 30096 | K16: 30096 | M16: 30096 | O16: 30096 | Q16: 30096 | S16: 30096 | U16: 30096 | W16: 30096 | Y16: 30096 | AA16: 30096 | AC16: 30096
A17: 15 | B17: Abhirami N A | C17: Project Associate (Community Development) | D17: LSGB | E17: 31762 | F17: 25 | G17: 26468.333 | H17: 24 | I17: 24589.935 | K17: 31762 | M17: 31762 | O17: 31762 | Q17: 31762 | S17: 31762 | U17: 31762 | W17: 31762 | Y17: 31762 | AA17: 31762 | AC17: 31762
A18: 16 | B18: Devika Prasad | C18: Project Associate (Community Development) | D18: CORE TEAM | E18: 32035 | F18: 28 | G18: 29899.333 | H18: 30.5 | I18: 31518.306 | K18: 32035 | M18: 32035 | O18: 32035 | Q18: 32035 | S18: 32035 | U18: 32035 | W18: 32035 | Y18: 32035 | AA18: 32035 | AC18: 32035
A19: 17 | B19: Jayalekshmi M J | C19: Project Associate (Community Development) | D19: LSGB | E19: 32035 | F19: 30 | G19: 32035 | H19: 30.5 | I19: 31518.306 | K19: 32035 | M19: 32035 | O19: 32035 | Q19: 32035 | S19: 32035 | U19: 32035 | W19: 32035 | Y19: 32035 | AA19: 32035 | AC19: 32035
A20: 18 | B20: K Anakha Soman | C20: Project Associate (Community Development) | D20: CORE TEAM | E20: 32035 | F20: 30 | G20: 32035 | H20: 31 | I20: 32035 | K20: 32035 | M20: 32035 | O20: 32035 | Q20: 32035 | S20: 32035 | U20: 32035 | W20: 32035 | Y20: 32035 | AA20: 32035 | AC20: 32035
A21: 19 | B21: Jithin Dominic | C21: Project Associate (Community Development) | D21: CORE TEAM | E21: 32035 | F21: 27.5 | G21: 29365.417 | H21: 31 | I21: 32035 | K21: 32035 | M21: 32035 | O21: 32035 | Q21: 32035 | S21: 32035 | U21: 32035 | W21: 32035 | Y21: 32035 | AA21: 32035 | AC21: 32035
A22: 20 | B22: Anjali A S | C22: Project Associate (Community Development) | D22: LSGB | E22: 31064 | F22: 30 | G22: 31064 | H22: 31 | I22: 31064 | K22: 31064 | M22: 31064 | O22: 31064 | Q22: 31064 | S22: 31064 | U22: 31064 | W22: 31064 | Y22: 31064 | AA22: 31064 | AC22: 31064
A23: 21 | B23: Rakhi Mohan | C23: Project Associate (Community Development) | D23: LSGB | E23: 31064 | F23: 28 | G23: 28993.067 | H23: 31 | I23: 31064 | K23: 31064 | M23: 31064 | O23: 31064 | Q23: 31064 | S23: 31064 | U23: 31064 | W23: 31064 | Y23: 31064 | AA23: 31064 | AC23: 31064
... A48: 46 | B48: Navya M | C48: Project Associate | D48: Powergrid CSR Thinkal | E48: 30156 | F48: 0 | G48: 0 | H48: 0 | I48: 0 | K48: 30156 | M48: 30156 | O48: 30156 | Q48: 30156 | S48: 30156 | U48: 30156 | W48: 30156 | Y48: 30156 | AA48: 30156 | AC48: 30156

Sheet AUGUST 2025 ADMIN EXPENSES
I1: HR @ 5% CSR | V1: HR Revenue | X1: ADMIN CHARGES TOTAL | AI1: TOTAL | AJ1: BALANCE
A2: Sl No | B2: Vendor | C2: Service | D2: Payment frequency | E2: Annual commitment | F2: Monthly Average | G2: Actual expense | I2: ='CORE MANPOWER'!AF2 -> HLL Malappuram | J2: ='CORE MANPOWER'!AG2 -> Power Grid Corporation of India Limited - Yelahanka, Bangalore | K2: ='CORE MANPOWER'!AH2 -> Cochin Shipyard Limited - Andaman | L2: ='CORE MANPOWER'!AI2 -> IOCL - Panipat | M2: ='CORE MANPOWER'!AJ2 -> HLL Cotton Hill, Trivandrum | N2: ='CORE MANPOWER'!AK2 -> Swasthya-An innovative behaviour change programme for Aneamia in women of reproductive age | O2: ='CORE MANPOWER'!AL2 -> Counselling support for transgender individuals-pre and post surgery and non surgical pathways in gender transition | P2: ='CORE MANPOWER'!AM2 -> Inclusive community mental health initiative in Wayanad district | ... S2: ='CORE MANPOWER'!AP2 -> HLL Maharashtra | T2: LSGB | U2: Additional LSGB | W2: Month | X2: ='CORE MANPOWER'!AF2 -> HLL Malappuram | Y2: ='CORE MANPOWER'!AG2 -> Power Grid Corporation of India Limited - Yelahanka, Bangalore | Z2: ='CORE MANPOWER'!AH2 -> Cochin Shipyard Limited - Andaman | AA2: ='CORE MANPOWER'!AI2 -> IOCL - Panipat | AB2: ='CORE MANPOWER'!AJ2 -> HLL Cotton Hill, Trivandrum | AC2: ='CORE MANPOWER'!AK2 -> Swasthya-An innovative behaviour change programme for Aneamia in women of reproductive age | AD2: ='CORE MANPOWER'!AL2 -> Counselling support for transgender individuals-pre and post surgery and non surgical pathways in gender transition | AE2: ='CORE MANPOWER'!AM2 -> Inclusive community mental health initiative in Wayanad district | ... AH2: ='CORE MANPOWER'!AP2 -> HLL Maharashtra | AI2: HMA HR REVENUE | AJ2: LSGB
A3: 1 | B3: Manjith Travels | C3: Contract Vehicle | D3: Monthly | E3: =F3*12 -> 523932 | F3: 43661 | G3: 43661 | H3: =G3+G4+G5+G6+G7+G8 -> 120513 | I3: ='PROJECT MASTER FILE - COPY'!P17/H3*G3 -> 14714.488 | J3: ='PROJECT MASTER FILE - COPY'!P30/H3*G3 -> 11875.236 | K3: ='PROJECT MASTER FILE - COPY'!P43/H3*G3 -> 6799.5125 | L3: ='PROJECT MASTER FILE - COPY'!$P56/H3*G3 -> 19255.866 | M3: ='PROJECT MASTER FILE - COPY'!P69/H3*F3 -> 0 | N3: ='PROJECT MASTER FILE - COPY'!P82/H3*G3 -> 2550.5418 | O3: ='PROJECT MASTER FILE - COPY'!P95/H3*G3 -> 12982.04 | P3: ='PROJECT MASTER FILE - COPY'!P108/H3*G3 -> 14608.011 | Q3: 0 | R3: ='PROJECT MASTER FILE - COPY'!O134/H3*F3 -> 0 | S3: ='PROJECT MASTER FILE - COPY'!O4/H3*F3 -> 0 | T3: =F3- (I3+J3+K3+L3+M3+N3+O3+P3+Q3+R3+S3) -> -39124.695 | U3: =G3-F3 -> 0 | V3: 60000 | W3: 45839 | X3: ='PROJECT MASTER FILE - COPY'!O18 -> 0 | Y3: ='PROJECT MASTER FILE - COPY'!O31 -> 0 | Z3: ='PROJECT MASTER FILE - COPY'!O44 -> 0 | AA3: ='PROJECT MASTER FILE - COPY'!O57 -> 0 | AB3: ='PROJECT MASTER FILE - COPY'!O70 -> 0 | AC3: ='PROJECT MASTER FILE - COPY'!O83 -> 0 | AD3: ='PROJECT MASTER FILE - COPY'!O96 -> 0 | AE3: ='PROJECT MASTER FILE - COPY'!O109 -> 0 | AF3: ='PROJECT MASTER FILE - COPY'!O122 -> 8333.3333 | AG3: 0 | AH3: ='PROJECT MASTER FILE - COPY'!O5 -> 0 | AI3: ='HMA HR REVNUE SHEET'!J6 -> 60000 | AJ3: =G10-(X3+Y3+Z3+AD3+AE3+AF3+AH3+AI3) -> 50766.667
A4: 2 | B4: Alchemy IBS | C4: Website | D4: Monthly | E4: 200000 | F4: 0 | I4: ='PROJECT MASTER FILE - COPY'!P17/H3*G4 -> 0 | J4: ='PROJECT MASTER FILE - COPY'!P30/H3*G4 -> 0 | K4: ='PROJECT MASTER FILE - COPY'!P43/H3*G4 -> 0 | L4: ='PROJECT MASTER FILE - COPY'!P56/H3*G4 -> 0 | M4: ='PROJECT MASTER FILE - COPY'!P69/H3*F4 -> 0 | N4: ='PROJECT MASTER FILE - COPY'!P82/H3*G4 -> 0 | O4: ='PROJECT MASTER FILE - COPY'!P95/H3*G4 -> 0 | P4: ='PROJECT MASTER FILE - COPY'!P108/H3*G4 -> 0 | Q4: ='PROJECT MASTER FILE - COPY'!O121/H3*F4 -> 0 | R4: ='PROJECT MASTER FILE - COPY'!O134/H3*F4 -> 0 | S4: ='PROJECT MASTER FILE - COPY'!O4/H3*F4 -> 0 | T4: =F4- (I4+J4+K4+L4+M4+N4+O4+P4+Q4+R4+S4) -> 0 | U4: =G4-F4 -> 0 | V4: ='HMA HR REVNUE SHEET'!L6 -> 423768 | W4: 45870 | X4: ='PROJECT MASTER FILE - COPY'!O19 -> 16207.25 | Y4: ='PROJECT MASTER FILE - COPY'!P31 -> 0 | Z4: ='PROJECT MASTER FILE - COPY'!P44 -> 0 | AA4: ='PROJECT MASTER FILE - COPY'!P57 -> 0 | AB4: ='PROJECT MASTER FILE - COPY'!P70 | AC4: ='PROJECT MASTER FILE - COPY'!P83 -> 0 | AD4: ='PROJECT MASTER FILE - COPY'!P96 -> 0 | AE4: ='PROJECT MASTER FILE - COPY'!P109 -> 0 | AF4: 0 | AG4: 0 | AH4: ='PROJECT MASTER FILE - COPY'!P5 -> 0 | AI4: 423768 | AJ4: =G11-(X4+Y4+Z4+AD4+AE4+AF4+AH4+AI4) -> -437998.25
A5: 3 | B5: Oval Blue Technologies | C5: Photocopier SDP | D5: Monthly | E5: 84000 | F5: =E5/12 -> 7000 | G5: 6344 | I5: ='PROJECT MASTER FILE - COPY'!P17/H3*G5 -> 2138.0343 | J5: ='PROJECT MASTER FILE - COPY'!P30/H3*G5 -> 1725.4871 | K5: ='PROJECT MASTER FILE - COPY'!P43/H3*G5 -> 987.97799 | L5: ='PROJECT MASTER FILE - COPY'!P56/H3*G5 -> 2797.9023 | M5: ='PROJECT MASTER FILE - COPY'!P69/H3*F5 -> 0 | N5: ='PROJECT MASTER FILE - COPY'!P82/H3*G5 -> 370.59703 | O5: 0 | P5: ='PROJECT MASTER FILE - COPY'!P108/H3*G5 -> 2122.5629 | Q5: 0 | R5: ='PROJECT MASTER FILE - COPY'!O134/H3*F5 -> 0 | S5: ='PROJECT MASTER FILE - COPY'!O4/H3*F5 -> 0 | T5: =G5- (I5+J5+K5+L5+M5+N5+O5+P5+Q5+R5+S5) -> -3798.5617 | U5: 0 | W5: 45901
A6: 4 | B6: Volks Electronics | C6: Desktop rental | D6: Monthly | E6: 720000 | F6: 57180 | G6: 57180 | I6: ='PROJECT MASTER FILE - COPY'!P17/H3*G6 -> 19270.618 | J6: ='PROJECT MASTER FILE - COPY'!P30/H3*G6 -> 15552.231 | K6: ='PROJECT MASTER FILE - COPY'!P43/H3*G6 -> 8904.8836 | L6: ='PROJECT MASTER FILE - COPY'!P56/H3*G6 -> 25218.167 | M6: ='PROJECT MASTER FILE - COPY'!P69/H3*F6 -> 0 | N6: ='PROJECT MASTER FILE - COPY'!P82/H3*G6 -> 3340.2803 | O6: 0 | P6: ='PROJECT MASTER FILE - COPY'!P108/H3*G6 -> 19131.171 | Q6: 0 | R6: ='PROJECT MASTER FILE - COPY'!O134/H3*F6 -> 0 | S6: ='PROJECT MASTER FILE - COPY'!O4/H3*F6 -> 0 | T6: =F6- (I6+J6+K6+L6+M6+N6+O6+P6+Q6+R6+S6) -> -34237.351 | U6: =G6-F6 -> 0 | W6: 45931
A7: 5 | B7: Asianet | C7: Internet Services | D7: Quarterly | E7: 56640 | F7: 0 | I7: ='PROJECT MASTER FILE - COPY'!P17/H3*G7 -> 0 | J7: ='PROJECT MASTER FILE - COPY'!P30/H3*G7 -> 0 | K7: ='PROJECT MASTER FILE - COPY'!P43/H3*G7 -> 0 | L7: ='PROJECT MASTER FILE - COPY'!P56/H3*G7 -> 0 | M7: ='PROJECT MASTER FILE - COPY'!P69/H3*F7 -> 0 | N7: ='PROJECT MASTER FILE - COPY'!P82/H3*G7 -> 0 | O7: ='PROJECT MASTER FILE - COPY'!P95/H3*G7 -> 0 | P7: ='PROJECT MASTER FILE - COPY'!P108/H3*G7 -> 0 | Q7: ='PROJECT MASTER FILE - COPY'!O121/H3*F7 -> 0 | R7: ='PROJECT MASTER FILE - COPY'!O134/H3*F7 -> 0 | S7: ='PROJECT MASTER FILE - COPY'!O4/H3*F7 -> 0 | T7: =F7- (I7+J7+K7+L7+M7+N7+O7+P7+Q7+R7+S7) -> 0 | U7: =G7-F7 -> 0 | W7: 45962
A8: 6 | B8: Stationary | C8: Stationary | E8: 200000 | F8: 0 | G8: 13328 | I8: ='PROJECT MASTER FILE - COPY'!P17/H3*G8 -> 4491.7593 | J8: ='PROJECT MASTER FILE - COPY'!P30/H3*G8 -> 3625.0461 | K8: ='PROJECT MASTER FILE - COPY'!P43/H3*G8 -> 2075.6259 | L8: ='PROJECT MASTER FILE - COPY'!P56/H3*G8 -> 5878.0646 | M8: ='PROJECT MASTER FILE - COPY'!P69/H3*F8 -> 0 | N8: ='PROJECT MASTER FILE - COPY'!P82/H3*G8 -> 778.5809 | O8: ='PROJECT MASTER FILE - COPY'!P95/H3*G8 -> 3962.9104 | P8: ='PROJECT MASTER FILE - COPY'!P108/H3*G8 -> 4459.2557 | Q8: ='PROJECT MASTER FILE - COPY'!O121/H3*F8 -> 0 | R8: ='PROJECT MASTER FILE - COPY'!O134/H3*F8 -> 0 | S8: ='PROJECT MASTER FILE - COPY'!O4/H3*F8 -> 0 | T8: =G8- (I8+J8+K8+L8+M8+N8+O8+P8+Q8+R8+S8) -> -11943.243 | U8: 0 | W8: 45992
I9: =SUM(I3:I8) -> 40614.9 | J9: =SUM(J3:J8) -> 32778 | K9: =SUM(K3:K8) -> 18768 | L9: =SUM(L3:L8) -> 53150 | M9: =SUM(M3:M8) -> 0 | N9: =SUM(N3:N8) -> 7040 | O9: =SUM(O3:O8) -> 16944.951 | P9: =SUM(P3:P8) -> 40321 | ... T9: =SUM(T3:T8) -> -89103.851 | U9: 0
A10: 7 | B10: Dr Anandam | C10: House Rent | D10: Monthly | E10: 1800000 | F10: =E10/12 -> 150000 | G10: 119100 | H10: =SUM(F10:F28) -> 601833.33 | X10: =X4 -> 16207.25 | Y10: =Y4 -> 0 | Z10: =Z4 -> 0 | AA10: =AA4 -> 0 | AB10: =AB4 | AC10: =AC4 -> 0 | AD10: =AD4 -> 0 | AE10: =AE4 -> 0 | ... AH10: =AH4 -> 0 | AI10: =G10-(X10+Y10+Z10+AA10+AB10+AC10+AD10+AE10+AF10+AG10+AH10) -> 102892.75
A11: 8 | B11: BSNL | C11: Land Line | D11: Monthly | E11: 24000 | F11: =E11/12 -> 2000 | G11: 1977 | X11: 0 | Y11: 0 | Z11: 0 | AA11: 0 | AB11: 0 | AC11: 0 | AD11: 0 | AE11: 0 | AF11: 0 | AG11: 0 | AH11: 0 | AI11: 1977 | AJ11: 1974
A12: 9 | B12: KSEB | C12: Electricity Bill | D12: Monthly | E12: 264000 | F12: =E12/12 -> 22000 | AJ12: 21303
A13: 10 | B13: KWA | C13: Water Bill | D13: Monthly | E13: 96000 | F13: =E13/12 -> 8000
A14: 11 | B14: Subramania Industries | C14: DG AMC | D14: Half Yearly | E14: 10000 | F14: =E14/12 -> 833.33333
A15: 12 | B15: Imprest | C15: Monthly Imprest | D15: Monthly | E15: 120000 | F15: =E15/12 -> 10000 | G15: 10000
A16: 13 | B16: Geejey Solutions | C16: Epabx AMC | D16: Half Yearly | E16: 8000 | F16: =E16/12 -> 666.66667 | AJ16: 4360
A17: 14 | B17: VRS infosystems | C17: Tally Software Renewal | D17: Annualy | E17: 16000 | F17: =E17/12 -> 1333.3333
A18: 15 | B18: M/sArmtech Computer Services | C18: CAMC computer hardware | D18: Quarterly | E18: 15000 | F18: =E18/12 -> 1250
A19: 16 | B19: Nu aire | C19: AC AMC | D19: Quarterly | E19: 36000 | F19: =E19/12 -> 3000
A20: 17 | B20: Miscellaneous | C20: Repair & Maintenance | D20: Monthly | E20: 50000 | F20: =E20/12 -> 4166.6667
A21: 18 | B21: Microsoft 365 | C21: Software | D21: Annualy | E21: 7000 | F21: =E21/12 -> 583.33333
A22: 19 | B22: Asterisk | C22: Photocopier (Admin & DVP) | D22: Monthly | E22: 60000 | F22: 5000 | G22: 4354 | X22: 0 | Y22: 0 | Z22: 0 | AA22: 0 | AB22: 0 | AC22: 0 | AD22: 0 | AE22: 0 | AF22: 0 | AG22: 0 | AH22: 0 | AI22: 2177 | AJ22: =G22/2 -> 2177
A23: 20 | B23: Indian Postal Department | C23: Speed post | D23: Monthly | E23: 120000 | F23: =E23/12 -> 10000 | G23: 2572 | X23: 0 | Y23: 0 | Z23: 0 | AA23: 0 | AB23: 0 | AC23: 0 | AD23: 0 | AE23: 0 | AF23: 0 | AG23: 0 | AH23: 0 | AI23: 0 | AJ23: 2572
A24: 21 | B24: Pradeep Kumar Cost Accountant | C24: Financial Consultant | D24: Monthly | E24: 1296000 | F24: =E24/12 -> 108000
A25: 22 | B25: Pradeep Kumar Cost Accountant | C25: Accounts Assistance | D25: Monthly | E25: 750000 | F25: =E25/12 -> 62500
A26: 23 | B26: Vismaya Services | C26: HK salary | D26: Monthly | E26: 600000 | F26: 50000 | G26: 46955 | X26: 0 | Y26: 0 | Z26: 0 | AA26: 0 | AB26: 0 | AC26: 0 | AD26: 0 | AE26: 0 | AF26: 0 | AG26: 0 | AH26: 0 | AI26: 46955 | AJ26: 46016
A27: 24 | B27: Vismaya Services | C27: My city salary | D27: Monthly | E27: 810000 | F27: 67500 | G27: 66207 | X27: 0 | Y27: 0 | Z27: 0 | AA27: 0 | AB27: 0 | AC27: 0 | AD27: 0 | AE27: 0 | AF27: 0 | AG27: 0 | AH27: 0 | AI27: 0 | AJ27: 66676
A28: 25 | B28: Naveen Security Services | C28: Security salary | D28: Monthly | E28: =F28*12 -> 1140000 | F28: 95000 | G28: 96550 | X28: 0 | Y28: 0 | Z28: 0 | AA28: 0 | AB28: 0 | AC28: 0 | AD28: 0 | AE28: 0 | AF28: 0 | AG28: 0 | AH28: 0 | AI28: 96550 | AJ28: 96550

Sheet SEPTEMBER 2025 ADMIN EXPENSES
I1: HR @ 5% CSR | V1: HR Revenue | X1: ADMIN CHARGES TOTAL | AI1: TOTAL | AJ1: BALANCE
A2: Sl No | B2: Vendor | C2: Service | D2: Payment frequency | E2: Annual commitment | F2: Monthly Average | G2: Actual expense | I2: ='CORE MANPOWER'!AF2 -> HLL Malappuram | J2: ='CORE MANPOWER'!AG2 -> Power Grid Corporation of India Limited - Yelahanka, Bangalore | K2: ='CORE MANPOWER'!AH2 -> Cochin Shipyard Limited - Andaman | L2: ='CORE MANPOWER'!AI2 -> IOCL - Panipat | M2: ='CORE MANPOWER'!AJ2 -> HLL Cotton Hill, Trivandrum | N2: ='CORE MANPOWER'!AK2 -> Swasthya-An innovative behaviour change programme for Aneamia in women of reproductive age | O2: ='CORE MANPOWER'!AL2 -> Counselling support for transgender individuals-pre and post surgery and non surgical pathways in gender transition | P2: ='CORE MANPOWER'!AM2 -> Inclusive community mental health initiative in Wayanad district | ... S2: ='CORE MANPOWER'!AP2 -> HLL Maharashtra | T2: LSGB | U2: Additional LSGB | W2: Month | X2: ='CORE MANPOWER'!AF2 -> HLL Malappuram | Y2: ='CORE MANPOWER'!AG2 -> Power Grid Corporation of India Limited - Yelahanka, Bangalore | Z2: ='CORE MANPOWER'!AH2 -> Cochin Shipyard Limited - Andaman | AA2: ='CORE MANPOWER'!AI2 -> IOCL - Panipat | AB2: ='CORE MANPOWER'!AJ2 -> HLL Cotton Hill, Trivandrum | AC2: ='CORE MANPOWER'!AK2 -> Swasthya-An innovative behaviour change programme for Aneamia in women of reproductive age | AD2: ='CORE MANPOWER'!AL2 -> Counselling support for transgender individuals-pre and post surgery and non surgical pathways in gender transition | AE2: ='CORE MANPOWER'!AM2 -> Inclusive community mental health initiative in Wayanad district | ... AH2: ='CORE MANPOWER'!AP2 -> HLL Maharashtra | AI2: HMA HR REVENUE | AJ2: LSGB
A3: 1 | B3: Manjith Travels | C3: Contract Vehicle | D3: Monthly | E3: =F3*12 -> 523932 | F3: 43661 | G3: 46000 | H3: =G3+G4+G5+G6+G7+G8 -> 123202.46 | I3: 5171 | J3: 5979 | K3: 3611 | L3: 2525 | M3: ='PROJECT MASTER FILE - COPY'!P69/H3*F3 -> 0 | N3: 603 | O3: 7757 | P3: 7557 | Q3: 0 | R3: ='PROJECT MASTER FILE - COPY'!O134/H3*F3 -> 0 | S3: ='PROJECT MASTER FILE - COPY'!O4/H3*F3 -> 0 | T3: 12797 | U3: 0 | V3: 60000 | W3: 45839 | X3: ='PROJECT MASTER FILE - COPY'!O18 -> 0 | Y3: ='PROJECT MASTER FILE - COPY'!O31 -> 0 | Z3: ='PROJECT MASTER FILE - COPY'!O44 -> 0 | AA3: ='PROJECT MASTER FILE - COPY'!O57 -> 0 | AB3: ='PROJECT MASTER FILE - COPY'!O70 -> 0 | AC3: ='PROJECT MASTER FILE - COPY'!O83 -> 0 | AD3: ='PROJECT MASTER FILE - COPY'!O96 -> 0 | AE3: ='PROJECT MASTER FILE - COPY'!O109 -> 0 | AF3: ='PROJECT MASTER FILE - COPY'!O122 -> 8333.3333 | AG3: 0 | AH3: ='PROJECT MASTER FILE - COPY'!O5 -> 0 | AI3: ='HMA HR REVNUE SHEET'!J6 -> 60000 | AJ3: =G10-(X3+Y3+Z3+AD3+AE3+AF3+AH3+AI3) -> 50766.667
